INFO:apscheduler.scheduler:Adding job tentatively -- it will be properly scheduled when the scheduler starts
INFO:apscheduler.scheduler:Added job "update_flight_info" to job store "default"
INFO:apscheduler.scheduler:Scheduler started
INFO:werkzeug:[31m[1mWARNING: This is a development server. Do not use it in a production deployment. Use a production WSGI server instead.[0m
 * Running on http://127.0.0.1:5000
INFO:werkzeug:[33mPress CTRL+C to quit[0m
ERROR:search_engine:Exception on / [GET]
Traceback (most recent call last):
  File "/Users/izzatfahmialasadi/Desktop/DMC/Project/name_search_engine/new-env/lib/python3.9/site-packages/flask/app.py", line 1463, in wsgi_app
    response = self.full_dispatch_request()
  File "/Users/izzatfahmialasadi/Desktop/DMC/Project/name_search_engine/new-env/lib/python3.9/site-packages/flask/app.py", line 872, in full_dispatch_request
    rv = self.handle_user_exception(e)
  File "/Users/izzatfahmialasadi/Desktop/DMC/Project/name_search_engine/new-env/lib/python3.9/site-packages/flask_cors/extension.py", line 176, in wrapped_function
    return cors_after_request(app.make_response(f(*args, **kwargs)))
  File "/Users/izzatfahmialasadi/Desktop/DMC/Project/name_search_engine/new-env/lib/python3.9/site-packages/flask/app.py", line 870, in full_dispatch_request
    rv = self.dispatch_request()
  File "/Users/izzatfahmialasadi/Desktop/DMC/Project/name_search_engine/new-env/lib/python3.9/site-packages/flask/app.py", line 855, in dispatch_request
    return self.ensure_sync(self.view_functions[rule.endpoint])(**view_args)  # type: ignore[no-any-return]
  File "/Users/izzatfahmialasadi/Desktop/DMC/Project/name_search_engine/new-env/lib/python3.9/site-packages/flask_cors/decorator.py", line 130, in wrapped_function
    resp = make_response(f(*args, **kwargs))
  File "/Users/izzatfahmialasadi/Desktop/DMC/Project/name_search_engine/new-env/lib/python3.9/site-packages/flask_limiter/extension.py", line 1299, in __inner
    return cast(R, flask.current_app.ensure_sync(obj)(*a, **k))
  File "/Users/izzatfahmialasadi/Desktop/DMC/Project/name_search_engine/new-env/lib/python3.9/site-packages/flask_login/utils.py", line 285, in decorated_view
    return current_app.login_manager.unauthorized()
  File "/Users/izzatfahmialasadi/Desktop/DMC/Project/name_search_engine/new-env/lib/python3.9/site-packages/flask_login/login_manager.py", line 187, in unauthorized
    flash(self.login_message, category=self.login_message_category)
  File "/Users/izzatfahmialasadi/Desktop/DMC/Project/name_search_engine/new-env/lib/python3.9/site-packages/flask/helpers.py", line 323, in flash
    session["_flashes"] = flashes
  File "/Users/izzatfahmialasadi/Desktop/DMC/Project/name_search_engine/new-env/lib/python3.9/site-packages/flask/sessions.py", line 102, in _fail
    raise RuntimeError(
RuntimeError: The session is unavailable because no secret key was set.  Set the secret_key on the application to something unique and secret.
INFO:werkzeug:127.0.0.1 - - [14/May/2024 22:04:35] "[35m[1mGET / HTTP/1.1[0m" 500 -
INFO:apscheduler.scheduler:Scheduler has been shut down
INFO:apscheduler.scheduler:Adding job tentatively -- it will be properly scheduled when the scheduler starts
INFO:apscheduler.scheduler:Added job "update_flight_info" to job store "default"
INFO:apscheduler.scheduler:Scheduler started
INFO:werkzeug:[31m[1mWARNING: This is a development server. Do not use it in a production deployment. Use a production WSGI server instead.[0m
 * Running on http://127.0.0.1:5000
INFO:werkzeug:[33mPress CTRL+C to quit[0m
ERROR:search_engine:Exception on / [GET]
Traceback (most recent call last):
  File "/Users/izzatfahmialasadi/Desktop/DMC/Project/name_search_engine/new-env/lib/python3.9/site-packages/flask/app.py", line 1463, in wsgi_app
    response = self.full_dispatch_request()
  File "/Users/izzatfahmialasadi/Desktop/DMC/Project/name_search_engine/new-env/lib/python3.9/site-packages/flask/app.py", line 872, in full_dispatch_request
    rv = self.handle_user_exception(e)
  File "/Users/izzatfahmialasadi/Desktop/DMC/Project/name_search_engine/new-env/lib/python3.9/site-packages/flask_cors/extension.py", line 176, in wrapped_function
    return cors_after_request(app.make_response(f(*args, **kwargs)))
  File "/Users/izzatfahmialasadi/Desktop/DMC/Project/name_search_engine/new-env/lib/python3.9/site-packages/flask/app.py", line 870, in full_dispatch_request
    rv = self.dispatch_request()
  File "/Users/izzatfahmialasadi/Desktop/DMC/Project/name_search_engine/new-env/lib/python3.9/site-packages/flask/app.py", line 855, in dispatch_request
    return self.ensure_sync(self.view_functions[rule.endpoint])(**view_args)  # type: ignore[no-any-return]
  File "/Users/izzatfahmialasadi/Desktop/DMC/Project/name_search_engine/new-env/lib/python3.9/site-packages/flask_cors/decorator.py", line 130, in wrapped_function
    resp = make_response(f(*args, **kwargs))
  File "/Users/izzatfahmialasadi/Desktop/DMC/Project/name_search_engine/new-env/lib/python3.9/site-packages/flask_limiter/extension.py", line 1299, in __inner
    return cast(R, flask.current_app.ensure_sync(obj)(*a, **k))
  File "/Users/izzatfahmialasadi/Desktop/DMC/Project/name_search_engine/new-env/lib/python3.9/site-packages/flask_login/utils.py", line 285, in decorated_view
    return current_app.login_manager.unauthorized()
  File "/Users/izzatfahmialasadi/Desktop/DMC/Project/name_search_engine/new-env/lib/python3.9/site-packages/flask_login/login_manager.py", line 187, in unauthorized
    flash(self.login_message, category=self.login_message_category)
  File "/Users/izzatfahmialasadi/Desktop/DMC/Project/name_search_engine/new-env/lib/python3.9/site-packages/flask/helpers.py", line 323, in flash
    session["_flashes"] = flashes
  File "/Users/izzatfahmialasadi/Desktop/DMC/Project/name_search_engine/new-env/lib/python3.9/site-packages/flask/sessions.py", line 102, in _fail
    raise RuntimeError(
RuntimeError: The session is unavailable because no secret key was set.  Set the secret_key on the application to something unique and secret.
INFO:werkzeug:127.0.0.1 - - [14/May/2024 22:14:26] "[35m[1mGET / HTTP/1.1[0m" 500 -
ERROR:search_engine:Exception on / [GET]
Traceback (most recent call last):
  File "/Users/izzatfahmialasadi/Desktop/DMC/Project/name_search_engine/new-env/lib/python3.9/site-packages/flask/app.py", line 1463, in wsgi_app
    response = self.full_dispatch_request()
  File "/Users/izzatfahmialasadi/Desktop/DMC/Project/name_search_engine/new-env/lib/python3.9/site-packages/flask/app.py", line 872, in full_dispatch_request
    rv = self.handle_user_exception(e)
  File "/Users/izzatfahmialasadi/Desktop/DMC/Project/name_search_engine/new-env/lib/python3.9/site-packages/flask_cors/extension.py", line 176, in wrapped_function
    return cors_after_request(app.make_response(f(*args, **kwargs)))
  File "/Users/izzatfahmialasadi/Desktop/DMC/Project/name_search_engine/new-env/lib/python3.9/site-packages/flask/app.py", line 870, in full_dispatch_request
    rv = self.dispatch_request()
  File "/Users/izzatfahmialasadi/Desktop/DMC/Project/name_search_engine/new-env/lib/python3.9/site-packages/flask/app.py", line 855, in dispatch_request
    return self.ensure_sync(self.view_functions[rule.endpoint])(**view_args)  # type: ignore[no-any-return]
  File "/Users/izzatfahmialasadi/Desktop/DMC/Project/name_search_engine/new-env/lib/python3.9/site-packages/flask_cors/decorator.py", line 130, in wrapped_function
    resp = make_response(f(*args, **kwargs))
  File "/Users/izzatfahmialasadi/Desktop/DMC/Project/name_search_engine/new-env/lib/python3.9/site-packages/flask_limiter/extension.py", line 1299, in __inner
    return cast(R, flask.current_app.ensure_sync(obj)(*a, **k))
  File "/Users/izzatfahmialasadi/Desktop/DMC/Project/name_search_engine/new-env/lib/python3.9/site-packages/flask_login/utils.py", line 285, in decorated_view
    return current_app.login_manager.unauthorized()
  File "/Users/izzatfahmialasadi/Desktop/DMC/Project/name_search_engine/new-env/lib/python3.9/site-packages/flask_login/login_manager.py", line 187, in unauthorized
    flash(self.login_message, category=self.login_message_category)
  File "/Users/izzatfahmialasadi/Desktop/DMC/Project/name_search_engine/new-env/lib/python3.9/site-packages/flask/helpers.py", line 323, in flash
    session["_flashes"] = flashes
  File "/Users/izzatfahmialasadi/Desktop/DMC/Project/name_search_engine/new-env/lib/python3.9/site-packages/flask/sessions.py", line 102, in _fail
    raise RuntimeError(
RuntimeError: The session is unavailable because no secret key was set.  Set the secret_key on the application to something unique and secret.
INFO:werkzeug:127.0.0.1 - - [14/May/2024 22:14:36] "[35m[1mGET / HTTP/1.1[0m" 500 -
INFO:apscheduler.scheduler:Scheduler has been shut down
INFO:apscheduler.scheduler:Adding job tentatively -- it will be properly scheduled when the scheduler starts
INFO:apscheduler.scheduler:Added job "update_flight_info" to job store "default"
INFO:apscheduler.scheduler:Scheduler started
INFO:apscheduler.scheduler:Scheduler has been shut down
INFO:apscheduler.scheduler:Adding job tentatively -- it will be properly scheduled when the scheduler starts
INFO:apscheduler.scheduler:Added job "update_flight_info" to job store "default"
INFO:apscheduler.scheduler:Scheduler started
INFO:apscheduler.scheduler:Scheduler has been shut down
INFO:apscheduler.scheduler:Adding job tentatively -- it will be properly scheduled when the scheduler starts
INFO:apscheduler.scheduler:Added job "update_flight_info" to job store "default"
INFO:apscheduler.scheduler:Scheduler started
